<?xml version="1.0"?>

<robot name="gripper_2f">

  <link name="base_gripper">
    <visual>
      <origin rpy="0 0 0" xyz="0 0 0"/>
      <geometry>
        <mesh filename="package://my_gripper_description/meshes/gripper_body.dae"/>
      </geometry>
    </visual>
    <collision>
      <origin rpy="0 0 0" xyz="0 0 0"/>
      <geometry>
        <mesh filename="package://my_gripper_description/meshes/gripper_body.stl" scale="0.001 0.001 0.001"/>
      </geometry>
    </collision>
    <inertial>
      <origin xyz="0 0.06 0.04" rpy="0 0 0"/>
      <mass value="0.5"/>
      <inertia
        ixx="0.01" ixy="0.0" ixz="0.0"
        iyy="0.01" iyz="0.0"
        izz="0.01"/>
  	</inertial>
  </link>

  <link name="finger_1">
    <visual>
      <origin rpy="0 0 0" xyz="0 0 0"/>
      <geometry>
          <mesh filename="package://my_gripper_description/meshes/finger_1.stl" scale="0.001 0.001 0.001"/>
      </geometry>
    </visual>
    <collision>
      <origin rpy="0 0 0" xyz="0 0 0"/>
      <geometry>
          <mesh filename="package://my_gripper_description/meshes/finger_1.stl" scale="0.001 0.001 0.001"/>
      </geometry>
    </collision>
    <inertial>
      <origin xyz="0 0 0.05" rpy="0 0 0"/>
      <mass value="0.01"/>
      <inertia
        ixx="0.001" ixy="0.0" ixz="0.0"
        iyy="0.001" iyz="0.0"
        izz="0.001"/>
      </inertial>
  </link>

  <link name="finger_2">
    <visual>
      <origin rpy="0 0 0" xyz="0 0 0"/>
      <geometry>
          <mesh filename="package://my_gripper_description/meshes/finger_2.stl" scale="0.001 0.001 0.001"/>
      </geometry>
    </visual>
    <collision>
     <origin rpy="0 0 0" xyz="0 0 0"/>
      <geometry>
          <mesh filename="package://my_gripper_description/meshes/finger_2.stl" scale="0.001 0.001 0.001"/>
      </geometry>
    </collision>
    <inertial>
      <origin xyz="0 0 0.05" rpy="0 0 0"/>
      <mass value="0.01"/>
      <inertia
        ixx="0.001" ixy="0.0" ixz="0.0"
        iyy="0.001" iyz="0.0"
        izz="0.001"/>
      </inertial>
  </link>

  <joint name="base_to_finger_1" type="prismatic">
    <parent link="base_gripper"/>
    <child link="finger_1"/>  
    <axis xyz="1 0 0"/>
    <origin rpy="0 0 0" xyz="0.012 0.111 0"/>
	  <limit effort="100" velocity="100" lower="0" upper="0.01"/>

  </joint>
  <transmission name="trans_base_to_finger_1">
      <type> transmission_interface/SimpleTransmission </type>
      <joint name="base_to_finger_1">
        <hardwareInterface> hardware_interface/EffortJointInterface </hardwareInterface>
      </joint>
      <actuator name="motor_base_to_finger_1">
        <hardwareInterface> hardware_interface/EffortJointInterface </hardwareInterface>
        <mechanicalReduction> 1 </mechanicalReduction>
      </actuator>
   </transmission>

  <joint name="base_to_finger_2" type="prismatic">
    <parent link="base_gripper"/>
    <child link="finger_2"/>  
    <axis xyz="1 0 0"/>
    <origin rpy="0 0 0" xyz="-0.012 0.111 0"/>
  	<limit effort="100" velocity="100" lower="-0.01" upper="0"/>   
    <mimic joint="base_to_finger_1" multiplier="-1.0" offset="0"/>

  </joint>
  <transmission name="trans_base_to_finger_2">
      <type> transmission_interface/SimpleTransmission </type>
      <joint name="base_to_finger_2">
        <hardwareInterface> hardware_interface/EffortJointInterface </hardwareInterface>
      </joint>
      <actuator name="motor_base_to_finger_2">
        <hardwareInterface> hardware_interface/EffortJointInterface </hardwareInterface>
        <mechanicalReduction> 1 </mechanicalReduction>
      </actuator>
  </transmission>

  <gazebo reference="finger_1">
    <material>Gazebo/Grey</material>
  </gazebo>
  <gazebo reference="finger_2">
    <material>Gazebo/Grey</material>
  </gazebo>
  <gazebo>
    <plugin filename="libgazebo_ros_control.so" name="gazebo_ros_control">
      <robotNamesapce>/gripper_2fs</robotNamesapce>
    </plugin>
  </gazebo>
  <gazebo>
          <!-- loading plugin: mimic joints works in gazebo now -->
      <plugin filename="libroboticsgroup_gazebo_mimic_joint_plugin.so" name="mimic_2f">
          <joint>base_to_finger_1</joint>
          <mimicJoint>base_to_finger_2</mimicJoint>
          <multiplier>-1.0</multiplier>
      </plugin>
      
  </gazebo>


</robot>


