<?xml version="1.0" ?>
<!-- =================================================================================== -->
<!-- |    This document was autogenerated by xacro from /home/arandsi1/lanited_ws/src/lanited/multi-robot_description/urdf/multi-robot_grippers.urdf.xacro | -->
<!-- |    EDITING THIS FILE BY HAND IS NOT RECOMMENDED                                 | -->
<!-- =================================================================================== -->
<robot name="multi_robots_cell_lanited">
    <!-- common stuff -->
    <gazebo>
        <plugin filename="libgazebo_ros_control.so" name="ros_control">
            <!--robotNamespace>/</robotNamespace-->
            <!--robotSimType>gazebo_ros_control/DefaultRobotHWSim</robotSimType-->
        </plugin>
        <!--
    <plugin name="gazebo_ros_power_monitor_controller" filename="libgazebo_ros_power_monitor.so">
      <alwaysOn>true</alwaysOn>
      <updateRate>1.0</updateRate>
      <timeout>5</timeout>
      <powerStateTopic>power_state</powerStateTopic>
      <powerStateRate>10.0</powerStateRate>
      <fullChargeCapacity>87.78</fullChargeCapacity>     
      <dischargeRate>-474</dischargeRate>
      <chargeRate>525</chargeRate>
      <dischargeVoltage>15.52</dischargeVoltage>
      <chargeVoltage>16.41</chargeVoltage>
    </plugin>
-->
        <plugin name="gazebo_ros_control">
            <robotNamespace>/</robotNamespace>
        </plugin>
    </gazebo>
    <link name="world" />
    <link name="eje_extern_part_1_link">
        <inertial>
            <origin rpy="0 0 0" xyz="0.137802209307 0.090396 0.0227196811405" />
            <mass value="21.80" />
            <inertia ixx="0.001" ixy="0.001" ixz="0.001" iyy="0.001" iyz="0.001" izz="0.001" />
        </inertial>
        <visual>
            <geometry>
                <mesh filename="package://eje_ext_description/meshes/eje_ext_ur_part-1.STL" />
            </geometry>
            <material name="LightGrey">
                <color rgba="0.7 0.7 0.7 1.0" />
            </material>
        </visual>
        <collision>
            <geometry>
                <mesh filename="package://eje_ext_description/meshes/eje_ext_ur_part-1.STL" />
            </geometry>
        </collision>
    </link>
    <gazebo reference="eje_extern_part_1_link">
        <material>Gazebo/Grey</material>
        <mu1>0.2</mu1>
        <mu2>0.2</mu2>
    </gazebo>
    <link name="eje_extern_part_2_link">
        <inertial>
            <origin rpy="0 0 0" xyz="0.137802209307 0.090396 0.0227196811405" />
            <mass value="21.80" />
            <inertia ixx="0.001" ixy="0.001" ixz="0.001" iyy="0.001" iyz="0.001" izz="0.001" />
        </inertial>
        <visual>
            <geometry>
                <mesh filename="package://eje_ext_description/meshes/eje_ext_ur_part-2.STL" />
            </geometry>
            <material name="LightGrey">
                <color rgba="0.7 0.7 0.7 1.0" />
            </material>
        </visual>
        <collision>
            <geometry>
                <mesh filename="package://eje_ext_description/meshes/eje_ext_ur_part-2.STL" />
            </geometry>
        </collision>
    </link>
    <gazebo reference="eje_extern_part_2_link">
        <material>Gazebo/Grey</material>
        <mu1>0.2</mu1>
        <mu2>0.2</mu2>
    </gazebo>
    <joint name="eje_extern_joint" type="prismatic">
        <parent link="eje_extern_part_1_link" />
        <child link="eje_extern_part_2_link" />
        <origin rpy="0.0 0.0 3.14160" xyz="-0.088 0.2275 0.06125" />
        <axis xyz="0 1 0" />
        <limit effort="30" lower="-1.3" upper="0" velocity="1.0" />
        <dynamics damping="1.0" />
    </joint>
    <transmission name="eje_extern_part_1_trans">
        <type>transmission_interface/SimpleTransmission</type>
        <joint name="eje_extern_joint">
            <hardwareInterface>hardware_interface/EffortJointInterface</hardwareInterface>
        </joint>
        <actuator name="eje_extern_part_1_motor">
            <hardwareInterface>hardware_interface/EffortJointInterface</hardwareInterface>
            <mechanicalReduction>1</mechanicalReduction>
        </actuator>
    </transmission>
    <gazebo reference="eje_extern_part_1_link">
        <selfCollide>true</selfCollide>
    </gazebo>
    <gazebo reference="eje_extern_part_2_link">
        <selfCollide>true</selfCollide>
    </gazebo>
    <joint name="world_joint" type="fixed">
        <parent link="world" />
        <child link="eje_extern_part_1_link" />
        <origin rpy="0.0 0.0 3.1416" xyz="0.530 0.765 0.87457" />
    </joint>
    <!-- measured from model -->
    <!--property name="shoulder_height" value="0.089159" /-->
    <!--property name="shoulder_offset" value="0.13585" /-->
    <!-- shoulder_offset - elbow_offset + wrist_1_length = 0.10915 -->
    <!--property name="upper_arm_length" value="0.42500" /-->
    <!--property name="elbow_offset" value="0.1197" /-->
    <!-- CAD measured -->
    <!--property name="forearm_length" value="0.39225" /-->
    <!--property name="wrist_1_length" value="0.093" /-->
    <!-- CAD measured -->
    <!--property name="wrist_2_length" value="0.09465" /-->
    <!-- In CAD this distance is 0.930, but in the spec it is 0.09465 -->
    <!--property name="wrist_3_length" value="0.0823" /-->
    <!-- manually measured -->
    <link name="ur5_B_base_link">
        <visual>
            <geometry>
                <mesh filename="package://ur_description/meshes/ur5/visual/base.dae" />
            </geometry>
            <material name="LightGrey">
                <color rgba="0.7 0.7 0.7 1.0" />
            </material>
        </visual>
        <collision>
            <geometry>
                <mesh filename="package://ur_description/meshes/ur5/collision/base.stl" />
            </geometry>
        </collision>
        <inertial>
            <mass value="4.0" />
            <origin rpy="0 0 0" xyz="0.0 0.0 0.0" />
            <inertia ixx="0.00443333156" ixy="0.0" ixz="0.0" iyy="0.00443333156" iyz="0.0" izz="0.0072" />
        </inertial>
    </link>
    <joint name="ur5_B_shoulder_pan_joint" type="revolute">
        <parent link="ur5_B_base_link" />
        <child link="ur5_B_shoulder_link" />
        <origin rpy="0.0 0.0 0.0" xyz="0.0 0.0 0.089159" />
        <axis xyz="0 0 1" />
        <limit effort="150.0" lower="-6.283185307179586" upper="6.283185307179586" velocity="3.15" />
        <dynamics damping="0.0" friction="0.0" />
    </joint>
    <link name="ur5_B_shoulder_link">
        <visual>
            <geometry>
                <mesh filename="package://ur_description/meshes/ur5/visual/shoulder.dae" />
            </geometry>
            <material name="LightGrey">
                <color rgba="0.7 0.7 0.7 1.0" />
            </material>
        </visual>
        <collision>
            <geometry>
                <mesh filename="package://ur_description/meshes/ur5/collision/shoulder.stl" />
            </geometry>
        </collision>
        <inertial>
            <mass value="3.7" />
            <origin rpy="0 0 0" xyz="0.0 0.0 0.0" />
            <inertia ixx="0.010267495893" ixy="0.0" ixz="0.0" iyy="0.010267495893" iyz="0.0" izz="0.00666" />
        </inertial>
    </link>
    <joint name="ur5_B_shoulder_lift_joint" type="revolute">
        <parent link="ur5_B_shoulder_link" />
        <child link="ur5_B_upper_arm_link" />
        <origin rpy="0.0 1.5707963267948966 0.0" xyz="0.0 0.13585 0.0" />
        <axis xyz="0 1 0" />
        <limit effort="150.0" lower="-6.283185307179586" upper="6.283185307179586" velocity="3.15" />
        <dynamics damping="0.0" friction="0.0" />
    </joint>
    <link name="ur5_B_upper_arm_link">
        <visual>
            <geometry>
                <mesh filename="package://ur_description/meshes/ur5/visual/upperarm.dae" />
            </geometry>
            <material name="LightGrey">
                <color rgba="0.7 0.7 0.7 1.0" />
            </material>
        </visual>
        <collision>
            <geometry>
                <mesh filename="package://ur_description/meshes/ur5/collision/upperarm.stl" />
            </geometry>
        </collision>
        <inertial>
            <mass value="8.393" />
            <origin rpy="0 0 0" xyz="0.0 0.0 0.28" />
            <inertia ixx="0.22689067591036005" ixy="0.0" ixz="0.0" iyy="0.22689067591036005" iyz="0.0" izz="0.0151074" />
        </inertial>
    </link>
    <joint name="ur5_B_elbow_joint" type="revolute">
        <parent link="ur5_B_upper_arm_link" />
        <child link="ur5_B_forearm_link" />
        <origin rpy="0.0 0.0 0.0" xyz="0.0 -0.1197 0.425" />
        <axis xyz="0 1 0" />
        <limit effort="150.0" lower="-3.141592653589793" upper="3.141592653589793" velocity="3.15" />
        <dynamics damping="0.0" friction="0.0" />
    </joint>
    <link name="ur5_B_forearm_link">
        <visual>
            <geometry>
                <mesh filename="package://ur_description/meshes/ur5/visual/forearm.dae" />
            </geometry>
            <material name="LightGrey">
                <color rgba="0.7 0.7 0.7 1.0" />
            </material>
        </visual>
        <collision>
            <geometry>
                <mesh filename="package://ur_description/meshes/ur5/collision/forearm.stl" />
            </geometry>
        </collision>
        <inertial>
            <mass value="2.275" />
            <origin rpy="0 0 0" xyz="0.0 0.0 0.196125" />
            <inertia ixx="0.03121679102890359" ixy="0.0" ixz="0.0" iyy="0.03121679102890359" iyz="0.0" izz="0.004095" />
        </inertial>
    </link>
    <joint name="ur5_B_wrist_1_joint" type="revolute">
        <parent link="ur5_B_forearm_link" />
        <child link="ur5_B_wrist_1_link" />
        <origin rpy="0.0 1.5707963267948966 0.0" xyz="0.0 0.0 0.39225" />
        <axis xyz="0 1 0" />
        <limit effort="28.0" lower="-6.283185307179586" upper="6.283185307179586" velocity="3.2" />
        <dynamics damping="0.0" friction="0.0" />
    </joint>
    <link name="ur5_B_wrist_1_link">
        <visual>
            <geometry>
                <mesh filename="package://ur_description/meshes/ur5/visual/wrist1.dae" />
            </geometry>
            <material name="LightGrey">
                <color rgba="0.7 0.7 0.7 1.0" />
            </material>
        </visual>
        <collision>
            <geometry>
                <mesh filename="package://ur_description/meshes/ur5/collision/wrist1.stl" />
            </geometry>
        </collision>
        <inertial>
            <mass value="1.219" />
            <origin rpy="0 0 0" xyz="0.0 0.093 0.0" />
            <inertia ixx="0.0025598989760400002" ixy="0.0" ixz="0.0" iyy="0.0025598989760400002" iyz="0.0" izz="0.0021942" />
        </inertial>
    </link>
    <joint name="ur5_B_wrist_2_joint" type="revolute">
        <parent link="ur5_B_wrist_1_link" />
        <child link="ur5_B_wrist_2_link" />
        <origin rpy="0.0 0.0 0.0" xyz="0.0 0.093 0.0" />
        <axis xyz="0 0 1" />
        <limit effort="28.0" lower="-6.283185307179586" upper="6.283185307179586" velocity="3.2" />
        <dynamics damping="0.0" friction="0.0" />
    </joint>
    <link name="ur5_B_wrist_2_link">
        <visual>
            <geometry>
                <mesh filename="package://ur_description/meshes/ur5/visual/wrist2.dae" />
            </geometry>
            <material name="LightGrey">
                <color rgba="0.7 0.7 0.7 1.0" />
            </material>
        </visual>
        <collision>
            <geometry>
                <mesh filename="package://ur_description/meshes/ur5/collision/wrist2.stl" />
            </geometry>
        </collision>
        <inertial>
            <mass value="1.219" />
            <origin rpy="0 0 0" xyz="0.0 0.0 0.09465" />
            <inertia ixx="0.0025598989760400002" ixy="0.0" ixz="0.0" iyy="0.0025598989760400002" iyz="0.0" izz="0.0021942" />
        </inertial>
    </link>
    <joint name="ur5_B_wrist_3_joint" type="revolute">
        <parent link="ur5_B_wrist_2_link" />
        <child link="ur5_B_wrist_3_link" />
        <origin rpy="0.0 0.0 0.0" xyz="0.0 0.0 0.09465" />
        <axis xyz="0 1 0" />
        <limit effort="28.0" lower="-6.283185307179586" upper="6.283185307179586" velocity="3.2" />
        <dynamics damping="0.0" friction="0.0" />
    </joint>
    <link name="ur5_B_wrist_3_link">
        <visual>
            <geometry>
                <mesh filename="package://ur_description/meshes/ur5/visual/wrist3.dae" />
            </geometry>
            <material name="LightGrey">
                <color rgba="0.7 0.7 0.7 1.0" />
            </material>
        </visual>
        <collision>
            <geometry>
                <mesh filename="package://ur_description/meshes/ur5/collision/wrist3.stl" />
            </geometry>
        </collision>
        <inertial>
            <mass value="0.1879" />
            <origin rpy="1.5707963267948966 0 0" xyz="0.0 0.06505 0.0" />
            <inertia ixx="8.469589112163e-05" ixy="0.0" ixz="0.0" iyy="8.469589112163e-05" iyz="0.0" izz="0.0001321171875" />
        </inertial>
    </link>
    <joint name="ur5_B_ee_fixed_joint" type="fixed">
        <parent link="ur5_B_wrist_3_link" />
        <child link="ur5_B_ee_link" />
        <origin rpy="0.0 0.0 1.5707963267948966" xyz="0.0 0.0823 0.0" />
    </joint>
    <link name="ur5_B_ee_link">
        <collision>
            <geometry>
                <box size="0.01 0.01 0.01" />
            </geometry>
            <origin rpy="0 0 0" xyz="-0.01 0 0" />
        </collision>
        <inertial>
            <mass value="0.1" />
            <origin xyz="0 0 0" rpy="0 0 0" />
            <inertia ixx="0.03" iyy="0.03" izz="0.03" ixy="0.0" ixz="0.0" iyz="0.0" />
        </inertial>
    </link>
    <transmission name="ur5_B_shoulder_pan_trans">
        <type>transmission_interface/SimpleTransmission</type>
        <joint name="ur5_B_shoulder_pan_joint">
            <hardwareInterface>hardware_interface/EffortJointInterface</hardwareInterface>
        </joint>
        <actuator name="ur5_B_shoulder_pan_motor">
            <mechanicalReduction>1</mechanicalReduction>
            <hardwareInterface>hardware_interface/EffortJointInterface</hardwareInterface>
        </actuator>
    </transmission>
    <transmission name="ur5_B_shoulder_lift_trans">
        <type>transmission_interface/SimpleTransmission</type>
        <joint name="ur5_B_shoulder_lift_joint">
            <hardwareInterface>hardware_interface/EffortJointInterface</hardwareInterface>
        </joint>
        <actuator name="ur5_B_shoulder_lift_motor">
            <mechanicalReduction>1</mechanicalReduction>
            <hardwareInterface>hardware_interface/EffortJointInterface</hardwareInterface>
        </actuator>
    </transmission>
    <transmission name="ur5_B_elbow_trans">
        <type>transmission_interface/SimpleTransmission</type>
        <joint name="ur5_B_elbow_joint">
            <hardwareInterface>hardware_interface/EffortJointInterface</hardwareInterface>
        </joint>
        <actuator name="ur5_B_elbow_motor">
            <mechanicalReduction>1</mechanicalReduction>
            <hardwareInterface>hardware_interface/EffortJointInterface</hardwareInterface>
        </actuator>
    </transmission>
    <transmission name="ur5_B_wrist_1_trans">
        <type>transmission_interface/SimpleTransmission</type>
        <joint name="ur5_B_wrist_1_joint">
            <hardwareInterface>hardware_interface/EffortJointInterface</hardwareInterface>
        </joint>
        <actuator name="ur5_B_wrist_1_motor">
            <mechanicalReduction>1</mechanicalReduction>
            <hardwareInterface>hardware_interface/EffortJointInterface</hardwareInterface>
        </actuator>
    </transmission>
    <transmission name="ur5_B_wrist_2_trans">
        <type>transmission_interface/SimpleTransmission</type>
        <joint name="ur5_B_wrist_2_joint">
            <hardwareInterface>hardware_interface/EffortJointInterface</hardwareInterface>
        </joint>
        <actuator name="ur5_B_wrist_2_motor">
            <mechanicalReduction>1</mechanicalReduction>
            <hardwareInterface>hardware_interface/EffortJointInterface</hardwareInterface>
        </actuator>
    </transmission>
    <transmission name="ur5_B_wrist_3_trans">
        <type>transmission_interface/SimpleTransmission</type>
        <joint name="ur5_B_wrist_3_joint">
            <hardwareInterface>hardware_interface/EffortJointInterface</hardwareInterface>
        </joint>
        <actuator name="ur5_B_wrist_3_motor">
            <mechanicalReduction>1</mechanicalReduction>
            <hardwareInterface>hardware_interface/EffortJointInterface</hardwareInterface>
        </actuator>
    </transmission>
    <gazebo reference="ur5_B_shoulder_link">
        <selfCollide>true</selfCollide>
    </gazebo>
    <gazebo reference="ur5_B_upper_arm_link">
        <selfCollide>true</selfCollide>
    </gazebo>
    <gazebo reference="ur5_B_forearm_link">
        <selfCollide>true</selfCollide>
    </gazebo>
    <gazebo reference="ur5_B_wrist_1_link">
        <selfCollide>true</selfCollide>
    </gazebo>
    <gazebo reference="ur5_B_wrist_3_link">
        <selfCollide>true</selfCollide>
    </gazebo>
    <gazebo reference="ur5_B_wrist_2_link">
        <selfCollide>true</selfCollide>
    </gazebo>
    <gazebo reference="ur5_B_ee_link">
        <selfCollide>true</selfCollide>
    </gazebo>
    <!-- ROS base_link to UR 'Base' Coordinates transform -->
    <link name="ur5_B_base" />
    <joint name="ur5_B_base_link-base_fixed_joint" type="fixed">
        <!-- NOTE: this rotation is only needed as long as base_link itself is
                 not corrected wrt the real robot (ie: rotated over 180
                 degrees)
      -->
        <origin rpy="0 0 -3.141592653589793" xyz="0 0 0" />
        <parent link="ur5_B_base_link" />
        <child link="ur5_B_base" />
    </joint>
    <!-- Frame coincident with all-zeros TCP on UR controller -->
    <link name="ur5_B_tool0" />
    <joint name="ur5_B_wrist_3_link-tool0_fixed_joint" type="fixed">
        <origin rpy="-1.5707963267948966 0 0" xyz="0 0.0823 0" />
        <parent link="ur5_B_wrist_3_link" />
        <child link="ur5_B_tool0" />
    </joint>
    <joint name="eje_ur5_B" type="fixed">
        <parent link="eje_extern_part_2_link" />
        <child link="ur5_B_base_link" />
        <origin rpy="0.0 0.0 0.0" xyz="0.0 0.0 0.05075" />
    </joint>
    <material name="silver">
        <color rgba="0.700 0.700 0.700 1.000" />
    </material>
    <link name="ur5_B_gripper_base_link">
        <inertial>
            <origin rpy="0 0 0" xyz="-4.898915958379213e-05 2.84756960271082e-06 0.06811082379774974" />
            <mass value="1.2646523179240972" />
            <inertia ixx="0.001504" ixy="-0.0" ixz="-3e-06" iyy="0.001812" iyz="0.0" izz="0.001053" />
        </inertial>
        <visual>
            <origin rpy="0 0 0" xyz="0 0 0" />
            <geometry>
                <mesh filename="package://onrobot_2fg7_description/meshes/base_link.stl" scale="0.001 0.001 0.001" />
            </geometry>
            <material name="silver" />
        </visual>
        <collision>
            <origin rpy="0 0 0" xyz="0 0 0" />
            <geometry>
                <mesh filename="package://onrobot_2fg7_description/meshes/base_link.stl" scale="0.001 0.001 0.001" />
            </geometry>
        </collision>
    </link>
    <link name="ur5_B_gripper_right_finger_link">
        <inertial>
            <origin rpy="0 0 0" xyz="0.017874296677847158 0.02949104051991925 0.01523421548622829" />
            <mass value="0.023219383355922288" />
            <inertia ixx="6e-06" ixy="-0.0" ixz="1e-06" iyy="5e-06" iyz="-0.0" izz="2e-06" />
        </inertial>
        <visual>
            <origin rpy="0 0 0" xyz="0.0 0.0 -0.0" />
            <geometry>
                <mesh filename="package://onrobot_2fg7_description/meshes/finger_link.STL" />
            </geometry>
            <material name="silver" />
        </visual>
        <collision name="right_finger_collision">
            <origin rpy="0 0 0" xyz="0.054361 0.029494 -0.12005" />
            <geometry>
                <mesh filename="package://onrobot_2fg7_description/meshes/finger_link.STL" />
            </geometry>
        </collision>
    </link>
    <link name="ur5_B_gripper_left_finger_link">
        <inertial>
            <origin rpy="0 0 0" xyz="0.004247703322119739 0.029496959480080673 0.015234215486237948" />
            <mass value="0.023219383355922288" />
            <inertia ixx="6e-06" ixy="-0.0" ixz="-1e-06" iyy="5e-06" iyz="0.0" izz="2e-06" />
        </inertial>
        <visual>
            <origin rpy="0 0 0" xyz="-0.0 0.0 -0.0" />
            <geometry>
                <mesh filename="package://onrobot_2fg7_description/meshes/finger_link.STL" />
            </geometry>
            <material name="silver" />
        </visual>
        <collision name="left_finger_collision">
            <origin rpy="0 0 0" xyz="-0.032239 0.029494 -0.12005" />
            <geometry>
                <mesh filename="package://onrobot_2fg7_description/meshes/finger_link.STL" />
            </geometry>
        </collision>
    </link>
    <joint name="ur5_B_gripper_left_finger_joint" type="prismatic">
        <origin rpy="0 0 1.5708" xyz="0.0902 -0.0 0.11325" />
        <parent link="ur5_B_gripper_base_link" />
        <child link="ur5_B_gripper_left_finger_link" />
        <axis xyz="0.0 1.0 0.0" />
        <limit effort="140" lower="0.0" upper="0.019" velocity="0.45" />
        <!-- total 0.38 -->
    </joint>
    <joint name="ur5_B_gripper_right_finger_joint" type="prismatic">
        <origin rpy="0 0 -1.5708" xyz="-0.0902 -0.0 0.11325" />
        <parent link="ur5_B_gripper_base_link" />
        <child link="ur5_B_gripper_right_finger_link" />
        <axis xyz="0.0 1.0 0.0" />
        <limit effort="140" lower="-0.019" upper="0.019" velocity="0.45" />
        <mimic joint="ur5_B_gripper_left_finger_joint" multiplier="1.0" />
    </joint>
    <transmission name="ur5_B_gripper_left_finger_joint_tran">
        <type>transmission_interface/SimpleTransmission</type>
        <joint name="ur5_B_gripper_left_finger_joint">
            <hardwareInterface>hardware_interface/PositionJointInterface</hardwareInterface>
        </joint>
        <actuator name="ur5_B_gripper_left_finger_joint_motor">
            <hardwareInterface>hardware_interface/PositionJointInterface</hardwareInterface>
            <mechanicalReduction>1</mechanicalReduction>
        </actuator>
    </transmission>
    <gazebo reference="ur5_B_gripper_base_link">
        <material>Gazebo/Grey</material>
        <implicitSpringDamper>1</implicitSpringDamper>
        <mu1>0.2</mu1>
        <mu2>0.2</mu2>
        <kp>100000000.0</kp>
        <kd>1.0</kd>
        <selfCollide>true</selfCollide>
        <gravity>true</gravity>
    </gazebo>
    <gazebo reference="ur5_B_gripper_right_finger_link">
        <material>Gazebo/Grey</material>
        <implicitSpringDamper>1</implicitSpringDamper>
        <mu1>0.2</mu1>
        <mu2>0.2</mu2>
        <kp>100000000.0</kp>
        <kd>1.0</kd>
        <selfCollide>true</selfCollide>
    </gazebo>
    <gazebo reference="ur5_B_gripper_left_finger_link">
        <material>Gazebo/Grey</material>
        <implicitSpringDamper>1</implicitSpringDamper>
        <mu1>0.2</mu1>
        <mu2>0.2</mu2>
        <kp>100000000.0</kp>
        <kd>1.0</kd>
        <selfCollide>true</selfCollide>
    </gazebo>
    <joint name="ur5_B_gripper_robot" type="fixed">
        <parent link="ur5_B_wrist_3_link" />
        <child link="ur5_B_gripper_base_link" />
        <origin rpy="-1.5708 0 0.0" xyz="0.0 0.07 0.0" />
    </joint>
    <gazebo>
        <plugin filename="libgazebo_grasp_fix.so" name="ur5_B_gripper_gazebo_grasp_fix">
            <arm>
                <arm_name>ur5_B_gripper_arm</arm_name>
                <palm_link>ur5_B_wrist_3_link</palm_link>
                <gripper_link>ur5_B_gripper_left_finger_link</gripper_link>
                <gripper_link>ur5_B_gripper_right_finger_link</gripper_link>
            </arm>
            <forces_angle_tolerance>80</forces_angle_tolerance>
            <update_rate>10</update_rate>
            <grip_count_threshold>1</grip_count_threshold>
            <max_grip_count>3</max_grip_count>
            <release_tolerance>0.01</release_tolerance>
            <disable_collisions_on_attach>false</disable_collisions_on_attach>
            <contact_topic>ur5_B_gripper_contact</contact_topic>
        </plugin>
    </gazebo>
    <gazebo>
        <!-- loading plugin: mimic joints works in gazebo now -->
        <plugin filename="libroboticsgroup_upatras_gazebo_mimic_joint_plugin.so" name="mimic_2FG7">
            <joint>ur5_B_gripper_left_finger_joint</joint>
            <mimicJoint>ur5_B_gripper_right_finger_joint</mimicJoint>
            <!--multiplier>1.0</multiplier>
              <offset>0.0</offset-->
        </plugin>
    </gazebo>
    <!--
  Author: Felix Messmer
-->
    <!-- measured from model -->
    <link name="ur3_A_base_link">
        <visual>
            <geometry>
                <mesh filename="package://ur_description/meshes/ur3/visual/base.dae" />
            </geometry>
            <material name="LightGrey">
                <color rgba="0.7 0.7 0.7 1.0" />
            </material>
        </visual>
        <collision>
            <geometry>
                <mesh filename="package://ur_description/meshes/ur3/collision/base.stl" />
            </geometry>
        </collision>
        <inertial>
            <mass value="2.0" />
            <origin rpy="0 0 0" xyz="0.0 0.0 0.0" />
            <inertia ixx="0.0030531654454" ixy="0.0" ixz="0.0" iyy="0.0030531654454" iyz="0.0" izz="0.005625" />
        </inertial>
    </link>
    <joint name="ur3_A_shoulder_pan_joint" type="revolute">
        <parent link="ur3_A_base_link" />
        <child link="ur3_A_shoulder_link" />
        <origin rpy="0.0 0.0 0.0" xyz="0.0 0.0 0.1519" />
        <axis xyz="0 0 1" />
        <limit effort="330.0" lower="-6.283185307179586" upper="6.283185307179586" velocity="2.16" />
        <dynamics damping="0.0" friction="0.0" />
    </joint>
    <link name="ur3_A_shoulder_link">
        <visual>
            <geometry>
                <mesh filename="package://ur_description/meshes/ur3/visual/shoulder.dae" />
            </geometry>
            <material name="LightGrey">
                <color rgba="0.7 0.7 0.7 1.0" />
            </material>
        </visual>
        <collision>
            <geometry>
                <mesh filename="package://ur_description/meshes/ur3/collision/shoulder.stl" />
            </geometry>
        </collision>
        <inertial>
            <mass value="2.0" />
            <origin rpy="0 0 0" xyz="0.0 0.0 0.0" />
            <inertia ixx="0.008093163429399999" ixy="0.0" ixz="0.0" iyy="0.008093163429399999" iyz="0.0" izz="0.005625" />
        </inertial>
    </link>
    <joint name="ur3_A_shoulder_lift_joint" type="revolute">
        <parent link="ur3_A_shoulder_link" />
        <child link="ur3_A_upper_arm_link" />
        <origin rpy="0.0 1.5707963267948966 0.0" xyz="0.0 0.1198 0.0" />
        <axis xyz="0 1 0" />
        <limit effort="330.0" lower="-6.283185307179586" upper="6.283185307179586" velocity="2.16" />
        <dynamics damping="0.0" friction="0.0" />
    </joint>
    <link name="ur3_A_upper_arm_link">
        <visual>
            <geometry>
                <mesh filename="package://ur_description/meshes/ur3/visual/upperarm.dae" />
            </geometry>
            <material name="LightGrey">
                <color rgba="0.7 0.7 0.7 1.0" />
            </material>
        </visual>
        <collision>
            <geometry>
                <mesh filename="package://ur_description/meshes/ur3/collision/upperarm.stl" />
            </geometry>
        </collision>
        <inertial>
            <mass value="3.42" />
            <origin rpy="0 0 0" xyz="0.0 0.0 0.121825" />
            <inertia ixx="0.021728483221103233" ixy="0.0" ixz="0.0" iyy="0.021728483221103233" iyz="0.0" izz="0.00961875" />
        </inertial>
    </link>
    <joint name="ur3_A_elbow_joint" type="revolute">
        <parent link="ur3_A_upper_arm_link" />
        <child link="ur3_A_forearm_link" />
        <origin rpy="0.0 0.0 0.0" xyz="0.0 -0.0925 0.24365" />
        <axis xyz="0 1 0" />
        <limit effort="150.0" lower="-3.141592653589793" upper="3.141592653589793" velocity="3.15" />
        <dynamics damping="0.0" friction="0.0" />
    </joint>
    <link name="ur3_A_forearm_link">
        <visual>
            <geometry>
                <mesh filename="package://ur_description/meshes/ur3/visual/forearm.dae" />
            </geometry>
            <material name="LightGrey">
                <color rgba="0.7 0.7 0.7 1.0" />
            </material>
        </visual>
        <collision>
            <geometry>
                <mesh filename="package://ur_description/meshes/ur3/collision/forearm.stl" />
            </geometry>
        </collision>
        <inertial>
            <mass value="1.26" />
            <origin rpy="0 0 0" xyz="0.0 0.0 0.106625" />
            <inertia ixx="0.006546806443776375" ixy="0.0" ixz="0.0" iyy="0.006546806443776375" iyz="0.0" izz="0.00354375" />
        </inertial>
    </link>
    <joint name="ur3_A_wrist_1_joint" type="revolute">
        <parent link="ur3_A_forearm_link" />
        <child link="ur3_A_wrist_1_link" />
        <origin rpy="0.0 1.5707963267948966 0.0" xyz="0.0 0.0 0.21325" />
        <axis xyz="0 1 0" />
        <limit effort="54.0" lower="-6.283185307179586" upper="6.283185307179586" velocity="3.2" />
        <dynamics damping="0.0" friction="0.0" />
    </joint>
    <link name="ur3_A_wrist_1_link">
        <visual>
            <geometry>
                <mesh filename="package://ur_description/meshes/ur3/visual/wrist1.dae" />
            </geometry>
            <material name="LightGrey">
                <color rgba="0.7 0.7 0.7 1.0" />
            </material>
        </visual>
        <collision>
            <geometry>
                <mesh filename="package://ur_description/meshes/ur3/collision/wrist1.stl" />
            </geometry>
        </collision>
        <inertial>
            <mass value="0.8" />
            <origin rpy="0 0 0" xyz="0.0 0.08505 0.0" />
            <inertia ixx="0.002084999166" ixy="0.0" ixz="0.0" iyy="0.002084999166" iyz="0.0" izz="0.00225" />
        </inertial>
    </link>
    <joint name="ur3_A_wrist_2_joint" type="revolute">
        <parent link="ur3_A_wrist_1_link" />
        <child link="ur3_A_wrist_2_link" />
        <origin rpy="0.0 0.0 0.0" xyz="0.0 0.08505 0.0" />
        <axis xyz="0 0 1" />
        <limit effort="54.0" lower="-6.283185307179586" upper="6.283185307179586" velocity="3.2" />
        <dynamics damping="0.0" friction="0.0" />
    </joint>
    <link name="ur3_A_wrist_2_link">
        <visual>
            <geometry>
                <mesh filename="package://ur_description/meshes/ur3/visual/wrist2.dae" />
            </geometry>
            <material name="LightGrey">
                <color rgba="0.7 0.7 0.7 1.0" />
            </material>
        </visual>
        <collision>
            <geometry>
                <mesh filename="package://ur_description/meshes/ur3/collision/wrist2.stl" />
            </geometry>
        </collision>
        <inertial>
            <mass value="0.8" />
            <origin rpy="0 0 0" xyz="0.0 0.0 0.08535" />
            <inertia ixx="0.002084999166" ixy="0.0" ixz="0.0" iyy="0.002084999166" iyz="0.0" izz="0.00225" />
        </inertial>
    </link>
    <joint name="ur3_A_wrist_3_joint" type="revolute">
        <parent link="ur3_A_wrist_2_link" />
        <child link="ur3_A_wrist_3_link" />
        <origin rpy="0.0 0.0 0.0" xyz="0.0 0.0 0.08535" />
        <axis xyz="0 1 0" />
        <limit effort="54.0" lower="-6.283185307179586" upper="6.283185307179586" velocity="3.2" />
        <dynamics damping="0.0" friction="0.0" />
    </joint>
    <link name="ur3_A_wrist_3_link">
        <visual>
            <geometry>
                <mesh filename="package://ur_description/meshes/ur3/visual/wrist3.dae" />
            </geometry>
            <material name="LightGrey">
                <color rgba="0.7 0.7 0.7 1.0" />
            </material>
        </visual>
        <collision>
            <geometry>
                <mesh filename="package://ur_description/meshes/ur3/collision/wrist3.stl" />
            </geometry>
        </collision>
        <inertial>
            <mass value="0.35" />
            <origin rpy="1.5707963267948966 0 0" xyz="0.0 0.0619 0.0" />
            <inertia ixx="0.00013626661215999998" ixy="0.0" ixz="0.0" iyy="0.00013626661215999998" iyz="0.0" izz="0.0001792" />
        </inertial>
    </link>
    <joint name="ur3_A_ee_fixed_joint" type="fixed">
        <parent link="ur3_A_wrist_3_link" />
        <child link="ur3_A_ee_link" />
        <origin rpy="0.0 0.0 1.5707963267948966" xyz="0.0 0.0819 0.0" />
    </joint>
    <link name="ur3_A_ee_link">
        <collision>
            <geometry>
                <box size="0.01 0.01 0.01" />
            </geometry>
            <origin rpy="0 0 0" xyz="-0.01 0 0" />
        </collision>
        <inertial>
            <mass value="0.1" />
            <origin xyz="0 0 0" rpy="0 0 0" />
            <inertia ixx="0.03" iyy="0.03" izz="0.03" ixy="0.0" ixz="0.0" iyz="0.0" />
        </inertial>
    </link>
    <transmission name="ur3_A_shoulder_pan_trans">
        <type>transmission_interface/SimpleTransmission</type>
        <joint name="ur3_A_shoulder_pan_joint">
            <hardwareInterface>hardware_interface/EffortJointInterface</hardwareInterface>
        </joint>
        <actuator name="ur3_A_shoulder_pan_motor">
            <mechanicalReduction>1</mechanicalReduction>
            <hardwareInterface>hardware_interface/EffortJointInterface</hardwareInterface>
        </actuator>
    </transmission>
    <transmission name="ur3_A_shoulder_lift_trans">
        <type>transmission_interface/SimpleTransmission</type>
        <joint name="ur3_A_shoulder_lift_joint">
            <hardwareInterface>hardware_interface/EffortJointInterface</hardwareInterface>
        </joint>
        <actuator name="ur3_A_shoulder_lift_motor">
            <mechanicalReduction>1</mechanicalReduction>
            <hardwareInterface>hardware_interface/EffortJointInterface</hardwareInterface>
        </actuator>
    </transmission>
    <transmission name="ur3_A_elbow_trans">
        <type>transmission_interface/SimpleTransmission</type>
        <joint name="ur3_A_elbow_joint">
            <hardwareInterface>hardware_interface/EffortJointInterface</hardwareInterface>
        </joint>
        <actuator name="ur3_A_elbow_motor">
            <mechanicalReduction>1</mechanicalReduction>
            <hardwareInterface>hardware_interface/EffortJointInterface</hardwareInterface>
        </actuator>
    </transmission>
    <transmission name="ur3_A_wrist_1_trans">
        <type>transmission_interface/SimpleTransmission</type>
        <joint name="ur3_A_wrist_1_joint">
            <hardwareInterface>hardware_interface/EffortJointInterface</hardwareInterface>
        </joint>
        <actuator name="ur3_A_wrist_1_motor">
            <mechanicalReduction>1</mechanicalReduction>
            <hardwareInterface>hardware_interface/EffortJointInterface</hardwareInterface>
        </actuator>
    </transmission>
    <transmission name="ur3_A_wrist_2_trans">
        <type>transmission_interface/SimpleTransmission</type>
        <joint name="ur3_A_wrist_2_joint">
            <hardwareInterface>hardware_interface/EffortJointInterface</hardwareInterface>
        </joint>
        <actuator name="ur3_A_wrist_2_motor">
            <mechanicalReduction>1</mechanicalReduction>
            <hardwareInterface>hardware_interface/EffortJointInterface</hardwareInterface>
        </actuator>
    </transmission>
    <transmission name="ur3_A_wrist_3_trans">
        <type>transmission_interface/SimpleTransmission</type>
        <joint name="ur3_A_wrist_3_joint">
            <hardwareInterface>hardware_interface/EffortJointInterface</hardwareInterface>
        </joint>
        <actuator name="ur3_A_wrist_3_motor">
            <mechanicalReduction>1</mechanicalReduction>
            <hardwareInterface>hardware_interface/EffortJointInterface</hardwareInterface>
        </actuator>
    </transmission>
    <gazebo reference="ur3_A_shoulder_link">
        <selfCollide>true</selfCollide>
    </gazebo>
    <gazebo reference="ur3_A_upper_arm_link">
        <selfCollide>true</selfCollide>
    </gazebo>
    <gazebo reference="ur3_A_forearm_link">
        <selfCollide>true</selfCollide>
    </gazebo>
    <gazebo reference="ur3_A_wrist_1_link">
        <selfCollide>true</selfCollide>
    </gazebo>
    <gazebo reference="ur3_A_wrist_3_link">
        <selfCollide>true</selfCollide>
    </gazebo>
    <gazebo reference="ur3_A_wrist_2_link">
        <selfCollide>true</selfCollide>
    </gazebo>
    <gazebo reference="ur3_A_ee_link">
        <selfCollide>true</selfCollide>
    </gazebo>
    <!-- ROS base_link to UR 'Base' Coordinates transform -->
    <link name="ur3_A_base" />
    <joint name="ur3_A_base_link-base_fixed_joint" type="fixed">
        <!-- NOTE: this rotation is only needed as long as base_link itself is
                 not corrected wrt the real robot (ie: rotated over 180
                 degrees)
      -->
        <origin rpy="0 0 -3.141592653589793" xyz="0 0 0" />
        <parent link="ur3_A_base_link" />
        <child link="ur3_A_base" />
    </joint>
    <!-- Frame coincident with all-zeros TCP on UR controller -->
    <link name="ur3_A_tool0" />
    <joint name="ur3_A_wrist_3_link-tool0_fixed_joint" type="fixed">
        <origin rpy="-1.5707963267948966 0 0" xyz="0 0.0819 0" />
        <parent link="ur3_A_wrist_3_link" />
        <child link="ur3_A_tool0" />
    </joint>
    <joint name="world_ur3_A" type="fixed">
        <parent link="world" />
        <child link="ur3_A_base_link" />
        <origin rpy="0.0 0.0 0.0" xyz="0.712 1.115 0.90582" />
    </joint>
    <!-- Gripper Vacuum -->
    <link name="ur3_A_vacuum_gripper">
        <gravity>0</gravity>
        <visual>
            <geometry>
                <mesh filename="package://multi-robot_description/meshes/vacuum_gripper.STL" />
            </geometry>
            <material name="LightGrey">
                <color rgba="0.7 0.7 0.7 1.0" />
            </material>
        </visual>
        <collision>
            <geometry>
                <mesh filename="package://multi-robot_description/meshes/vacuum_gripper.STL" />
            </geometry>
        </collision>
        <inertial>
            <origin rpy="0 0 0" xyz="0.000000 0.000000 0.000000" />
            <mass value="0.0001" />
            <inertia ixx="1e-08" ixy="0" ixz="0" iyy="1e-08" iyz="0" izz="1e-08" />
        </inertial>
    </link>
    <joint name="ur3_A_vacuum_gripper_joint" type="fixed">
        <parent link="ur3_A_wrist_3_link" />
        <child link="ur3_A_vacuum_gripper" />
        <origin rpy="-1.5708 0 0.0" xyz="0.0 0.075 0.0" />
    </joint>
    <gazebo>
        <plugin filename="libgazebo_ros_vacuum_gripper.so" name="gazebo_ros_vacuum_gripper">
            <robotNamespace>/robot/multi_robots_cell_lanited</robotNamespace>
            <bodyName>ur3_A_vacuum_gripper</bodyName>
            <topicName>ur3_A_grasping</topicName>
        </plugin>
    </gazebo>
    <!-- measured from model -->
    <link name="ur3_C_base_link">
        <visual>
            <geometry>
                <mesh filename="package://ur_description/meshes/ur3/visual/base.dae" />
            </geometry>
            <material name="LightGrey">
                <color rgba="0.7 0.7 0.7 1.0" />
            </material>
        </visual>
        <collision>
            <geometry>
                <mesh filename="package://ur_description/meshes/ur3/collision/base.stl" />
            </geometry>
        </collision>
        <inertial>
            <mass value="2.0" />
            <origin rpy="0 0 0" xyz="0.0 0.0 0.0" />
            <inertia ixx="0.0030531654454" ixy="0.0" ixz="0.0" iyy="0.0030531654454" iyz="0.0" izz="0.005625" />
        </inertial>
    </link>
    <joint name="ur3_C_shoulder_pan_joint" type="revolute">
        <parent link="ur3_C_base_link" />
        <child link="ur3_C_shoulder_link" />
        <origin rpy="0.0 0.0 0.0" xyz="0.0 0.0 0.1519" />
        <axis xyz="0 0 1" />
        <limit effort="330.0" lower="-6.283185307179586" upper="6.283185307179586" velocity="2.16" />
        <dynamics damping="0.0" friction="0.0" />
    </joint>
    <link name="ur3_C_shoulder_link">
        <visual>
            <geometry>
                <mesh filename="package://ur_description/meshes/ur3/visual/shoulder.dae" />
            </geometry>
            <material name="LightGrey">
                <color rgba="0.7 0.7 0.7 1.0" />
            </material>
        </visual>
        <collision>
            <geometry>
                <mesh filename="package://ur_description/meshes/ur3/collision/shoulder.stl" />
            </geometry>
        </collision>
        <inertial>
            <mass value="2.0" />
            <origin rpy="0 0 0" xyz="0.0 0.0 0.0" />
            <inertia ixx="0.008093163429399999" ixy="0.0" ixz="0.0" iyy="0.008093163429399999" iyz="0.0" izz="0.005625" />
        </inertial>
    </link>
    <joint name="ur3_C_shoulder_lift_joint" type="revolute">
        <parent link="ur3_C_shoulder_link" />
        <child link="ur3_C_upper_arm_link" />
        <origin rpy="0.0 1.5707963267948966 0.0" xyz="0.0 0.1198 0.0" />
        <axis xyz="0 1 0" />
        <limit effort="330.0" lower="-6.283185307179586" upper="6.283185307179586" velocity="2.16" />
        <dynamics damping="0.0" friction="0.0" />
    </joint>
    <link name="ur3_C_upper_arm_link">
        <visual>
            <geometry>
                <mesh filename="package://ur_description/meshes/ur3/visual/upperarm.dae" />
            </geometry>
            <material name="LightGrey">
                <color rgba="0.7 0.7 0.7 1.0" />
            </material>
        </visual>
        <collision>
            <geometry>
                <mesh filename="package://ur_description/meshes/ur3/collision/upperarm.stl" />
            </geometry>
        </collision>
        <inertial>
            <mass value="3.42" />
            <origin rpy="0 0 0" xyz="0.0 0.0 0.121825" />
            <inertia ixx="0.021728483221103233" ixy="0.0" ixz="0.0" iyy="0.021728483221103233" iyz="0.0" izz="0.00961875" />
        </inertial>
    </link>
    <joint name="ur3_C_elbow_joint" type="revolute">
        <parent link="ur3_C_upper_arm_link" />
        <child link="ur3_C_forearm_link" />
        <origin rpy="0.0 0.0 0.0" xyz="0.0 -0.0925 0.24365" />
        <axis xyz="0 1 0" />
        <limit effort="150.0" lower="-3.141592653589793" upper="3.141592653589793" velocity="3.15" />
        <dynamics damping="0.0" friction="0.0" />
    </joint>
    <link name="ur3_C_forearm_link">
        <visual>
            <geometry>
                <mesh filename="package://ur_description/meshes/ur3/visual/forearm.dae" />
            </geometry>
            <material name="LightGrey">
                <color rgba="0.7 0.7 0.7 1.0" />
            </material>
        </visual>
        <collision>
            <geometry>
                <mesh filename="package://ur_description/meshes/ur3/collision/forearm.stl" />
            </geometry>
        </collision>
        <inertial>
            <mass value="1.26" />
            <origin rpy="0 0 0" xyz="0.0 0.0 0.106625" />
            <inertia ixx="0.006546806443776375" ixy="0.0" ixz="0.0" iyy="0.006546806443776375" iyz="0.0" izz="0.00354375" />
        </inertial>
    </link>
    <joint name="ur3_C_wrist_1_joint" type="revolute">
        <parent link="ur3_C_forearm_link" />
        <child link="ur3_C_wrist_1_link" />
        <origin rpy="0.0 1.5707963267948966 0.0" xyz="0.0 0.0 0.21325" />
        <axis xyz="0 1 0" />
        <limit effort="54.0" lower="-6.283185307179586" upper="6.283185307179586" velocity="3.2" />
        <dynamics damping="0.0" friction="0.0" />
    </joint>
    <link name="ur3_C_wrist_1_link">
        <visual>
            <geometry>
                <mesh filename="package://ur_description/meshes/ur3/visual/wrist1.dae" />
            </geometry>
            <material name="LightGrey">
                <color rgba="0.7 0.7 0.7 1.0" />
            </material>
        </visual>
        <collision>
            <geometry>
                <mesh filename="package://ur_description/meshes/ur3/collision/wrist1.stl" />
            </geometry>
        </collision>
        <inertial>
            <mass value="0.8" />
            <origin rpy="0 0 0" xyz="0.0 0.08505 0.0" />
            <inertia ixx="0.002084999166" ixy="0.0" ixz="0.0" iyy="0.002084999166" iyz="0.0" izz="0.00225" />
        </inertial>
    </link>
    <joint name="ur3_C_wrist_2_joint" type="revolute">
        <parent link="ur3_C_wrist_1_link" />
        <child link="ur3_C_wrist_2_link" />
        <origin rpy="0.0 0.0 0.0" xyz="0.0 0.08505 0.0" />
        <axis xyz="0 0 1" />
        <limit effort="54.0" lower="-6.283185307179586" upper="6.283185307179586" velocity="3.2" />
        <dynamics damping="0.0" friction="0.0" />
    </joint>
    <link name="ur3_C_wrist_2_link">
        <visual>
            <geometry>
                <mesh filename="package://ur_description/meshes/ur3/visual/wrist2.dae" />
            </geometry>
            <material name="LightGrey">
                <color rgba="0.7 0.7 0.7 1.0" />
            </material>
        </visual>
        <collision>
            <geometry>
                <mesh filename="package://ur_description/meshes/ur3/collision/wrist2.stl" />
            </geometry>
        </collision>
        <inertial>
            <mass value="0.8" />
            <origin rpy="0 0 0" xyz="0.0 0.0 0.08535" />
            <inertia ixx="0.002084999166" ixy="0.0" ixz="0.0" iyy="0.002084999166" iyz="0.0" izz="0.00225" />
        </inertial>
    </link>
    <joint name="ur3_C_wrist_3_joint" type="revolute">
        <parent link="ur3_C_wrist_2_link" />
        <child link="ur3_C_wrist_3_link" />
        <origin rpy="0.0 0.0 0.0" xyz="0.0 0.0 0.08535" />
        <axis xyz="0 1 0" />
        <limit effort="54.0" lower="-6.283185307179586" upper="6.283185307179586" velocity="3.2" />
        <dynamics damping="0.0" friction="0.0" />
    </joint>
    <link name="ur3_C_wrist_3_link">
        <visual>
            <geometry>
                <mesh filename="package://ur_description/meshes/ur3/visual/wrist3.dae" />
            </geometry>
            <material name="LightGrey">
                <color rgba="0.7 0.7 0.7 1.0" />
            </material>
        </visual>
        <collision>
            <geometry>
                <mesh filename="package://ur_description/meshes/ur3/collision/wrist3.stl" />
            </geometry>
        </collision>
        <inertial>
            <mass value="0.35" />
            <origin rpy="1.5707963267948966 0 0" xyz="0.0 0.0619 0.0" />
            <inertia ixx="0.00013626661215999998" ixy="0.0" ixz="0.0" iyy="0.00013626661215999998" iyz="0.0" izz="0.0001792" />
        </inertial>
    </link>
    <joint name="ur3_C_ee_fixed_joint" type="fixed">
        <parent link="ur3_C_wrist_3_link" />
        <child link="ur3_C_ee_link" />
        <origin rpy="0.0 0.0 1.5707963267948966" xyz="0.0 0.0819 0.0" />
    </joint>
    <link name="ur3_C_ee_link">
        <collision>
            <geometry>
                <box size="0.01 0.01 0.01" />
            </geometry>
            <origin rpy="0 0 0" xyz="-0.01 0 0" />
        </collision>
        <inertial>
            <mass value="0.1" />
            <origin xyz="0 0 0" rpy="0 0 0" />
            <inertia ixx="0.03" iyy="0.03" izz="0.03" ixy="0.0" ixz="0.0" iyz="0.0" />
        </inertial>
    </link>
    <transmission name="ur3_C_shoulder_pan_trans">
        <type>transmission_interface/SimpleTransmission</type>
        <joint name="ur3_C_shoulder_pan_joint">
            <hardwareInterface>hardware_interface/EffortJointInterface</hardwareInterface>
        </joint>
        <actuator name="ur3_C_shoulder_pan_motor">
            <mechanicalReduction>1</mechanicalReduction>
            <hardwareInterface>hardware_interface/EffortJointInterface</hardwareInterface>
        </actuator>
    </transmission>
    <transmission name="ur3_C_shoulder_lift_trans">
        <type>transmission_interface/SimpleTransmission</type>
        <joint name="ur3_C_shoulder_lift_joint">
            <hardwareInterface>hardware_interface/EffortJointInterface</hardwareInterface>
        </joint>
        <actuator name="ur3_C_shoulder_lift_motor">
            <mechanicalReduction>1</mechanicalReduction>
            <hardwareInterface>hardware_interface/EffortJointInterface</hardwareInterface>
        </actuator>
    </transmission>
    <transmission name="ur3_C_elbow_trans">
        <type>transmission_interface/SimpleTransmission</type>
        <joint name="ur3_C_elbow_joint">
            <hardwareInterface>hardware_interface/EffortJointInterface</hardwareInterface>
        </joint>
        <actuator name="ur3_C_elbow_motor">
            <mechanicalReduction>1</mechanicalReduction>
            <hardwareInterface>hardware_interface/EffortJointInterface</hardwareInterface>
        </actuator>
    </transmission>
    <transmission name="ur3_C_wrist_1_trans">
        <type>transmission_interface/SimpleTransmission</type>
        <joint name="ur3_C_wrist_1_joint">
            <hardwareInterface>hardware_interface/EffortJointInterface</hardwareInterface>
        </joint>
        <actuator name="ur3_C_wrist_1_motor">
            <mechanicalReduction>1</mechanicalReduction>
            <hardwareInterface>hardware_interface/EffortJointInterface</hardwareInterface>
        </actuator>
    </transmission>
    <transmission name="ur3_C_wrist_2_trans">
        <type>transmission_interface/SimpleTransmission</type>
        <joint name="ur3_C_wrist_2_joint">
            <hardwareInterface>hardware_interface/EffortJointInterface</hardwareInterface>
        </joint>
        <actuator name="ur3_C_wrist_2_motor">
            <mechanicalReduction>1</mechanicalReduction>
            <hardwareInterface>hardware_interface/EffortJointInterface</hardwareInterface>
        </actuator>
    </transmission>
    <transmission name="ur3_C_wrist_3_trans">
        <type>transmission_interface/SimpleTransmission</type>
        <joint name="ur3_C_wrist_3_joint">
            <hardwareInterface>hardware_interface/EffortJointInterface</hardwareInterface>
        </joint>
        <actuator name="ur3_C_wrist_3_motor">
            <mechanicalReduction>1</mechanicalReduction>
            <hardwareInterface>hardware_interface/EffortJointInterface</hardwareInterface>
        </actuator>
    </transmission>
    <gazebo reference="ur3_C_shoulder_link">
        <selfCollide>true</selfCollide>
    </gazebo>
    <gazebo reference="ur3_C_upper_arm_link">
        <selfCollide>true</selfCollide>
    </gazebo>
    <gazebo reference="ur3_C_forearm_link">
        <selfCollide>true</selfCollide>
    </gazebo>
    <gazebo reference="ur3_C_wrist_1_link">
        <selfCollide>true</selfCollide>
    </gazebo>
    <gazebo reference="ur3_C_wrist_3_link">
        <selfCollide>true</selfCollide>
    </gazebo>
    <gazebo reference="ur3_C_wrist_2_link">
        <selfCollide>true</selfCollide>
    </gazebo>
    <gazebo reference="ur3_C_ee_link">
        <selfCollide>true</selfCollide>
    </gazebo>
    <!-- ROS base_link to UR 'Base' Coordinates transform -->
    <link name="ur3_C_base" />
    <joint name="ur3_C_base_link-base_fixed_joint" type="fixed">
        <!-- NOTE: this rotation is only needed as long as base_link itself is
                 not corrected wrt the real robot (ie: rotated over 180
                 degrees)
      -->
        <origin rpy="0 0 -3.141592653589793" xyz="0 0 0" />
        <parent link="ur3_C_base_link" />
        <child link="ur3_C_base" />
    </joint>
    <!-- Frame coincident with all-zeros TCP on UR controller -->
    <link name="ur3_C_tool0" />
    <joint name="ur3_C_wrist_3_link-tool0_fixed_joint" type="fixed">
        <origin rpy="-1.5707963267948966 0 0" xyz="0 0.0819 0" />
        <parent link="ur3_C_wrist_3_link" />
        <child link="ur3_C_tool0" />
    </joint>
    <joint name="world_ur3_C" type="fixed">
        <parent link="world" />
        <child link="ur3_C_base_link" />
        <origin rpy="0.0 0.0 0.0" xyz="0.680 -1.115 0.90582" />
    </joint>
    <link name="ur3_C_gripper_base_link">
        <inertial>
            <origin rpy="0 0 0" xyz="-4.898915958379213e-05 2.84756960271082e-06 0.06811082379774974" />
            <mass value="1.2646523179240972" />
            <inertia ixx="0.001504" ixy="-0.0" ixz="-3e-06" iyy="0.001812" iyz="0.0" izz="0.001053" />
        </inertial>
        <visual>
            <origin rpy="0 0 0" xyz="0 0 0" />
            <geometry>
                <mesh filename="package://onrobot_2fg7_description/meshes/base_link.stl" scale="0.001 0.001 0.001" />
            </geometry>
            <material name="silver" />
        </visual>
        <collision>
            <origin rpy="0 0 0" xyz="0 0 0" />
            <geometry>
                <mesh filename="package://onrobot_2fg7_description/meshes/base_link.stl" scale="0.001 0.001 0.001" />
            </geometry>
        </collision>
    </link>
    <link name="ur3_C_gripper_right_finger_link">
        <inertial>
            <origin rpy="0 0 0" xyz="0.017874296677847158 0.02949104051991925 0.01523421548622829" />
            <mass value="0.023219383355922288" />
            <inertia ixx="6e-06" ixy="-0.0" ixz="1e-06" iyy="5e-06" iyz="-0.0" izz="2e-06" />
        </inertial>
        <visual>
            <origin rpy="0 0 0" xyz="0.0 0.0 -0.0" />
            <geometry>
                <mesh filename="package://onrobot_2fg7_description/meshes/finger_link.STL" />
            </geometry>
            <material name="silver" />
        </visual>
        <collision name="right_finger_collision">
            <origin rpy="0 0 0" xyz="0.054361 0.029494 -0.12005" />
            <geometry>
                <mesh filename="package://onrobot_2fg7_description/meshes/finger_link.STL" />
            </geometry>
        </collision>
    </link>
    <link name="ur3_C_gripper_left_finger_link">
        <inertial>
            <origin rpy="0 0 0" xyz="0.004247703322119739 0.029496959480080673 0.015234215486237948" />
            <mass value="0.023219383355922288" />
            <inertia ixx="6e-06" ixy="-0.0" ixz="-1e-06" iyy="5e-06" iyz="0.0" izz="2e-06" />
        </inertial>
        <visual>
            <origin rpy="0 0 0" xyz="-0.0 0.0 -0.0" />
            <geometry>
                <mesh filename="package://onrobot_2fg7_description/meshes/finger_link.STL" />
            </geometry>
            <material name="silver" />
        </visual>
        <collision name="left_finger_collision">
            <origin rpy="0 0 0" xyz="-0.032239 0.029494 -0.12005" />
            <geometry>
                <mesh filename="package://onrobot_2fg7_description/meshes/finger_link.STL" />
            </geometry>
        </collision>
    </link>
    <joint name="ur3_C_gripper_left_finger_joint" type="prismatic">
        <origin rpy="0 0 1.5708" xyz="0.0902 -0.0 0.11325" />
        <parent link="ur3_C_gripper_base_link" />
        <child link="ur3_C_gripper_left_finger_link" />
        <axis xyz="0.0 1.0 0.0" />
        <limit effort="140" lower="0.0" upper="0.019" velocity="0.45" />
        <!-- total 0.38 -->
    </joint>
    <joint name="ur3_C_gripper_right_finger_joint" type="prismatic">
        <origin rpy="0 0 -1.5708" xyz="-0.0902 -0.0 0.11325" />
        <parent link="ur3_C_gripper_base_link" />
        <child link="ur3_C_gripper_right_finger_link" />
        <axis xyz="0.0 1.0 0.0" />
        <limit effort="140" lower="-0.019" upper="0.019" velocity="0.45" />
        <mimic joint="ur3_C_gripper_left_finger_joint" multiplier="1.0" />
    </joint>
    <transmission name="ur3_C_gripper_left_finger_joint_tran">
        <type>transmission_interface/SimpleTransmission</type>
        <joint name="ur3_C_gripper_left_finger_joint">
            <hardwareInterface>hardware_interface/PositionJointInterface</hardwareInterface>
        </joint>
        <actuator name="ur3_C_gripper_left_finger_joint_motor">
            <hardwareInterface>hardware_interface/PositionJointInterface</hardwareInterface>
            <mechanicalReduction>1</mechanicalReduction>
        </actuator>
    </transmission>
    <gazebo reference="ur3_C_gripper_base_link">
        <material>Gazebo/Grey</material>
        <implicitSpringDamper>1</implicitSpringDamper>
        <mu1>0.2</mu1>
        <mu2>0.2</mu2>
        <kp>100000000.0</kp>
        <kd>1.0</kd>
        <selfCollide>true</selfCollide>
        <gravity>true</gravity>
    </gazebo>
    <gazebo reference="ur3_C_gripper_right_finger_link">
        <material>Gazebo/Grey</material>
        <implicitSpringDamper>1</implicitSpringDamper>
        <mu1>0.2</mu1>
        <mu2>0.2</mu2>
        <kp>100000000.0</kp>
        <kd>1.0</kd>
        <selfCollide>true</selfCollide>
    </gazebo>
    <gazebo reference="ur3_C_gripper_left_finger_link">
        <material>Gazebo/Grey</material>
        <implicitSpringDamper>1</implicitSpringDamper>
        <mu1>0.2</mu1>
        <mu2>0.2</mu2>
        <kp>100000000.0</kp>
        <kd>1.0</kd>
        <selfCollide>true</selfCollide>
    </gazebo>
    <joint name="ur3_C_gripper_robot" type="fixed">
        <parent link="ur3_C_wrist_3_link" />
        <child link="ur3_C_gripper_base_link" />
        <origin rpy="-1.5708 0 0.0" xyz="0.0 0.07 0.0" />
    </joint>
    <gazebo>
        <plugin filename="libgazebo_grasp_fix.so" name="ur3_C_gripper_gazebo_grasp_fix">
            <arm>
                <arm_name>ur3_C_gripper_arm</arm_name>
                <palm_link>ur3_C_wrist_3_link</palm_link>
                <gripper_link>ur3_C_gripper_left_finger_link</gripper_link>
                <gripper_link>ur3_C_gripper_right_finger_link</gripper_link>
            </arm>
            <forces_angle_tolerance>80</forces_angle_tolerance>
            <update_rate>10</update_rate>
            <grip_count_threshold>1</grip_count_threshold>
            <max_grip_count>3</max_grip_count>
            <release_tolerance>0.01</release_tolerance>
            <disable_collisions_on_attach>false</disable_collisions_on_attach>
            <contact_topic>ur3_C_gripper_contact</contact_topic>
        </plugin>
    </gazebo>
    <gazebo>
        <!-- loading plugin: mimic joints works in gazebo now -->
        <plugin filename="libroboticsgroup_upatras_gazebo_mimic_joint_plugin.so" name="mimic_2FG7">
            <joint>ur3_C_gripper_left_finger_joint</joint>
            <mimicJoint>ur3_C_gripper_right_finger_joint</mimicJoint>
            <!--multiplier>1.0</multiplier>
              <offset>0.0</offset-->
        </plugin>
    </gazebo>
    <transmission name="trans_ur5_B_gripper_right_finger_joint">
        <type>transmission_interface/SimpleTransmission</type>
        <joint name="ur5_B_gripper_right_finger_joint">
            <hardwareInterface>hardware_interface/EffortJointInterface</hardwareInterface>
        </joint>
        <actuator name="ur5_B_gripper_right_finger_joint_motor">
            <hardwareInterface>hardware_interface/EffortJointInterface</hardwareInterface>
            <mechanicalReduction>1</mechanicalReduction>
        </actuator>
    </transmission>
    <transmission name="trans_ur3_C_gripper_right_finger_joint">
        <type>transmission_interface/SimpleTransmission</type>
        <joint name="ur3_C_gripper_right_finger_joint">
            <hardwareInterface>hardware_interface/EffortJointInterface</hardwareInterface>
        </joint>
        <actuator name="ur3_C_gripper_right_finger_joint_motor">
            <hardwareInterface>hardware_interface/EffortJointInterface</hardwareInterface>
            <mechanicalReduction>1</mechanicalReduction>
        </actuator>
    </transmission>
</robot>

